<mujoco model="tilburg_hand">
<option timestep="0.01111" iterations="50" integrator="Euler" collision="predefined" gravity="0 0 -9.81" />
  <compiler angle="radian" autolimits="true"/>
  <default/>
  <asset>
    <mesh name="handbase_and_motors_collision" file="handbase_and_motors_collision.stl"/>
    <mesh name="thumb_mcp_collision" file="thumb_mcp_collision.stl"/>
    <mesh name="test_thumb_roll_mcp_collision" file="test_thumb_roll_mcp_collision.stl"/>
    <mesh name="proximal_phalange_collision" file="proximal_phalange_collision.stl"/>
    <mesh name="thumb_distal_collision" file="thumb_distal_collision.stl"/>
    <mesh name="mcp_3_collision" file="mcp_3_collision.stl"/>
    <mesh name="proximal_phalange_2_collision" file="proximal_phalange_2_collision.stl"/>
    <mesh name="middle_phalange_collision" file="middle_phalange_collision.stl"/>
    <mesh name="distal_finalshape_collision" file="distal_finalshape_collision.stl"/>
    <mesh name="mcp_3_2_collision" file="mcp_3_2_collision.stl"/>
    <mesh name="proximal_phalange_3_collision" file="proximal_phalange_3_collision.stl"/>
    <mesh name="middle_phalange_2_collision" file="middle_phalange_2_collision.stl"/>
    <mesh name="distal_finalshape_2_collision" file="distal_finalshape_2_collision.stl"/>
    <mesh name="mcp_3_3_collision" file="mcp_3_3_collision.stl"/>
    <mesh name="proximal_phalange_4_collision" file="proximal_phalange_4_collision.stl"/>
    <mesh name="middle_phalange_3_collision" file="middle_phalange_3_collision.stl"/>
    <mesh name="distal_finalshape_3_collision" file="distal_finalshape_3_collision.stl"/>
  </asset>
  <worldbody>
<body name="hand_base" pos="0 0 0" euler="0 0 0">    <geom name="handbase_and_motors" conaffinity="1" contype="1" friction="1 0.005 0.001" margin="0.001" solimp="0.95 0.95 0.01" solref="0.008 1" type="mesh" rgba="0.615865 0.649203 0.705643 1" mesh="handbase_and_motors_collision"/>
    <body name="thumb_mcp" pos="0.0459067 0.0814877 -0.0103767" quat="0.0403773 -0.0219363 -0.674586 0.736765" gravcomp="0">
      <inertial pos="-0.00336008 0.0104245 0.0140112" quat="0.705399 0.708685 -0.00389937 -0.0127609" mass="0.0259261" diaginertia="4.44074e-06 4.37503e-06 2.95984e-06"/>
      <joint armature="0.01" damping="0.4" stiffness="0.3" frictionloss="0.01" ref="0" springref="0" margin="0.01" name="thumb_cmc" pos="0 0 0" axis="0 0 1" range="0 1.5708"/>
      <geom name="thumb_thumb_mcp" conaffinity="1" contype="1" friction="1 0.005 0.001" margin="0.001" solimp="0.95 0.95 0.01" solref="0.008 1" type="mesh" rgba="0.871558 0.93709 0.976409 1" mesh="thumb_mcp_collision"/>
      <body name="test_thumb_roll_mcp" pos="-0.01699 0 0.014" quat="0.707107 0 -0.707107 0" gravcomp="0">
        <inertial pos="-0.000503967 0.00367437 0.00891183" quat="0.441307 0.548539 0.474465 0.528428" mass="0.0051287" diaginertia="1.09205e-06 9.52622e-07 4.71781e-07"/>
        <joint armature="0.01" damping="0.4" stiffness="0.3" frictionloss="0.01" ref="0" springref="0" margin="0.01" name="thumb_mcp_rot" pos="0 0 0" axis="0 0 1" range="-1.74533 0"/>
        <geom name="thumb_test_thumb_roll_mcp" conaffinity="1" contype="1" friction="1 0.005 0.001" margin="0.001" solimp="0.95 0.95 0.01" solref="0.008 1" type="mesh" rgba="0.231373 0.380392 0.705882 1" mesh="test_thumb_roll_mcp_collision"/>
        <body name="proximal_phalange" pos="0.0131 -1.07477e-06 0.0185" quat="0.5 -0.5 0.5 -0.5" gravcomp="0">
          <inertial pos="0.00105525 -0.0248 -0.0139711" quat="0.707098 0.707098 -0.00349569 0.00349569" mass="0.0420084" diaginertia="1.8062e-05 1.71932e-05 4.27729e-06"/>
          <joint armature="0.01" damping="0.4" stiffness="0.3" frictionloss="0.01" ref="0" springref="0" margin="0.01" name="thumb_mcp" pos="0 0 0" axis="0 0 1" range="0 1.5708"/>
          <geom name="thumb_proximal_phalange" conaffinity="1" contype="1" friction="1 0.005 0.001" margin="0.001" solimp="0.95 0.95 0.01" solref="0.008 1" type="mesh" rgba="0.996506 0.963661 0.868622 1" mesh="proximal_phalange_collision"/>
          <body name="thumb_distal" pos="0 -0.0496 0" quat="0.707107 0 0 -0.707107" gravcomp="0">
            <inertial pos="0.0361694 5.09546e-05 -0.0132835" quat="0.493044 0.486424 0.504201 0.51583" mass="0.01279" diaginertia="5.91941e-06 5.23433e-06 1.78431e-06"/>
            <joint armature="0.01" damping="0.4" stiffness="0.3" frictionloss="0.01" ref="0" springref="0" margin="0.01" name="thumb_ip" pos="0 0 0" axis="0 0 1" range="0 1.6581"/>
            <geom name="thumb_thumb_distal" conaffinity="1" contype="1" friction="1 0.005 0.001" margin="0.001" solimp="0.95 0.95 0.01" solref="0.008 1" type="mesh" rgba="0.513726 0.415686 0.733333 1" mesh="thumb_distal_collision"/>
          </body>
        </body>
      </body>
    </body>
    <body name="mcp_3" pos="0.0538972 0.140661 -0.00372245" quat="0.997976 -0.0439674 0.0130398 -0.0440624" gravcomp="0">
      <inertial pos="-0.00048757 0.0155243 -0.0117405" quat="0.719022 -0.283303 0.16479 0.612855" mass="0.00917755" diaginertia="2.25958e-06 2.05723e-06 1.86647e-06"/>
      <joint armature="0.01" damping="0.4" stiffness="0.3" frictionloss="0.01" ref="0" springref="0" margin="0.01" name="index_mcp_abadd" pos="0 0 0" axis="0 0 1" range="-0.436332 0.436332"/>
      <geom name="index_mcp_3" conaffinity="1" contype="1" friction="1 0.005 0.001" margin="0.001" solimp="0.95 0.95 0.01" solref="0.008 1" type="mesh" rgba="0.231373 0.380392 0.705882 1" mesh="mcp_3_collision"/>
      <body name="proximal_phalange_2" pos="0.0131 0.0325 -0.00659893" quat="0.0308436 0.706434 0.0308436 0.706434" gravcomp="0">
        <inertial pos="0.00105525 -0.0248 -0.0139711" quat="0.707098 0.707098 -0.00349569 0.00349569" mass="0.0420084" diaginertia="1.8062e-05 1.71932e-05 4.27729e-06"/>
        <joint armature="0.01" damping="0.4" stiffness="0.3" frictionloss="0.01" ref="0" springref="0" margin="0.01" name="index_mcp" pos="0 0 0" axis="0 0 1" range="-0.0873 1.6581"/>
        <geom name="index_proximal_phalange_2" conaffinity="1" contype="1" friction="1 0.005 0.001" margin="0.001" solimp="0.95 0.95 0.01" solref="0.008 1" type="mesh" rgba="0.996506 0.963661 0.868622 1" mesh="proximal_phalange_2_collision"/>
        <body name="middle_phalange" pos="0 -0.0496 0" quat="0.67559 0 0 -0.737277" gravcomp="0">
          <inertial pos="0.0297882 0.000739764 -0.0138886" quat="0.491469 0.482081 0.50191 0.523586" mass="0.0257193" diaginertia="6.56033e-06 5.56532e-06 3.02948e-06"/>
          <joint armature="0.01" damping="0.4" stiffness="0.3" frictionloss="0.01" ref="0" springref="0" margin="0.01" name="index_pip" pos="0 0 0" axis="0 0 1" range="-0.0873 1.6581"/>
          <geom name="index_middle_phalange" conaffinity="1" contype="1" friction="1 0.005 0.001" margin="0.001" solimp="0.95 0.95 0.01" solref="0.008 1" type="mesh" rgba="0.958732 0.818161 0.775603 1" mesh="middle_phalange_collision"/>
          <body name="distal_finalshape" pos="0.0423 0 -1e-05" quat="0.999048 0.000871834 3.80651e-05 -0.0436194" gravcomp="0">
            <inertial pos="0.0280291 -0.000103785 -0.0133295" quat="0.490667 0.474831 0.50425 0.528691" mass="0.00905" diaginertia="2.9933e-06 2.44126e-06 1.2834e-06"/>
            <joint armature="0.01" damping="0.4" stiffness="0.3" frictionloss="0.01" ref="0" springref="0" margin="0.01" name="index_dip" pos="0 0 0" axis="0 0 1" range="-0.0873 1.6581"/>
            <geom name="index_distal_finalshape" conaffinity="1" contype="1" friction="1 0.005 0.001" margin="0.001" solimp="0.95 0.95 0.01" solref="0.008 1" type="mesh" rgba="0.513726 0.415686 0.733333 1" mesh="distal_finalshape_collision"/>
          </body>
        </body>
      </body>
    </body>
    <body name="mcp_3_2" pos="0.00982995 0.142679 -0.00257471" quat="0.998948 -0.0433568 0.0149452 -0.000489352" gravcomp="0">
      <inertial pos="-0.00048757 0.0155243 -0.0117405" quat="0.719022 -0.283303 0.16479 0.612855" mass="0.00917755" diaginertia="2.25958e-06 2.05723e-06 1.86647e-06"/>
      <joint armature="0.01" damping="0.4" stiffness="0.3" frictionloss="0.01" ref="0" springref="0" margin="0.01" name="middle_mcp_abadd" pos="0 0 0" axis="0 0 1" range="-0.436332 0.436332"/>
      <geom name="middle_mcp_3_2" conaffinity="1" contype="1" friction="1 0.005 0.001" margin="0.001" solimp="0.95 0.95 0.01" solref="0.008 1" type="mesh" rgba="0.231373 0.380392 0.705882 1" mesh="mcp_3_2_collision"/>
      <body name="proximal_phalange_3" pos="0.0131 0.0325 -0.00659893" quat="0.0304446 0.706451 0.0304446 0.706451" gravcomp="0">
        <inertial pos="0.00105525 -0.0248 -0.0139711" quat="0.707098 0.707098 -0.00349569 0.00349569" mass="0.0420084" diaginertia="1.8062e-05 1.71932e-05 4.27729e-06"/>
        <joint armature="0.01" damping="0.4" stiffness="0.3" frictionloss="0.01" ref="0" springref="0" margin="0.01" name="middle_mcp" pos="0 0 0" axis="0 0 1" range="-0.0873 1.6581"/>
        <geom name="middle_proximal_phalange_3" conaffinity="1" contype="1" friction="1 0.005 0.001" margin="0.001" solimp="0.95 0.95 0.01" solref="0.008 1" type="mesh" rgba="0.996506 0.963661 0.868622 1" mesh="proximal_phalange_3_collision"/>
        <body name="middle_phalange_2" pos="0 -0.0496 0" quat="0.67588 0 0 -0.737012" gravcomp="0">
          <inertial pos="0.0297882 0.000739764 -0.0138886" quat="0.491469 0.482081 0.50191 0.523586" mass="0.0257193" diaginertia="6.56033e-06 5.56532e-06 3.02948e-06"/>
          <joint armature="0.01" damping="0.4" stiffness="0.3" frictionloss="0.01" ref="0" springref="0" margin="0.01" name="middle_pip" pos="0 0 0" axis="0 0 1" range="-0.0873 1.6581"/>
          <geom name="middle_middle_phalange_2" conaffinity="1" contype="1" friction="1 0.005 0.001" margin="0.001" solimp="0.95 0.95 0.01" solref="0.008 1" type="mesh" rgba="0.958732 0.818161 0.775603 1" mesh="middle_phalange_2_collision"/>
          <body name="distal_finalshape_2" pos="0.0423 0 -1e-05" quat="0.999054 0.000871839 3.79378e-05 -0.0434735" gravcomp="0">
            <inertial pos="0.0280291 -0.000103785 -0.0133295" quat="0.490667 0.474831 0.50425 0.528691" mass="0.00905" diaginertia="2.9933e-06 2.44126e-06 1.2834e-06"/>
            <joint armature="0.01" damping="0.4" stiffness="0.3" frictionloss="0.01" ref="0" springref="0" margin="0.01" name="middle_dip" pos="0 0 0" axis="0 0 1" range="-0.0873 1.6581"/>
            <geom name="middle_distal_finalshape_2" conaffinity="1" contype="1" friction="1 0.005 0.001" margin="0.001" solimp="0.95 0.95 0.01" solref="0.008 1" type="mesh" rgba="0.513726 0.415686 0.733333 1" mesh="distal_finalshape_2_collision"/>
          </body>
        </body>
      </body>
    </body>
    <body name="mcp_3_3" pos="-0.03465 0.140579 0.00196625" quat="0.998018 -0.0426636 0.0168222 0.0430846" gravcomp="0">
      <inertial pos="-0.00048757 0.0155243 -0.0117405" quat="0.719022 -0.283303 0.16479 0.612855" mass="0.00917755" diaginertia="2.25958e-06 2.05723e-06 1.86647e-06"/>
      <joint armature="0.01" damping="0.4" stiffness="0.3" frictionloss="0.01" ref="0" springref="0" margin="0.01" name="ring_mcp_abadd" pos="0 0 0" axis="0 0 1" range="-0.436332 0.436332"/>
      <geom name="ring_mcp_3_3" conaffinity="1" contype="1" friction="1 0.005 0.001" margin="0.001" solimp="0.95 0.95 0.01" solref="0.008 1" type="mesh" rgba="0.231373 0.380392 0.705882 1" mesh="mcp_3_3_collision"/>
      <body name="proximal_phalange_4" pos="0.0131 0.0325 -0.00659893" quat="0.0276998 0.706564 0.0276998 0.706564" gravcomp="0">
        <inertial pos="0.00105525 -0.0248 -0.0139711" quat="0.707098 0.707098 -0.00349569 0.00349569" mass="0.0420084" diaginertia="1.8062e-05 1.71932e-05 4.27729e-06"/>
        <joint armature="0.01" damping="0.4" stiffness="0.3" frictionloss="0.01" ref="0" springref="0" margin="0.01" name="ring_mcp" pos="0 0 0" axis="0 0 1" range="-0.0873 1.6581"/>
        <geom name="ring_proximal_phalange_4" conaffinity="1" contype="1" friction="1 0.005 0.001" margin="0.001" solimp="0.95 0.95 0.01" solref="0.008 1" type="mesh" rgba="0.996506 0.963661 0.868622 1" mesh="proximal_phalange_4_collision"/>
        <body name="middle_phalange_3" pos="0 -0.0496 0" quat="0.67559 0 0 -0.737277" gravcomp="0">
          <inertial pos="0.0297882 0.000739764 -0.0138886" quat="0.491469 0.482081 0.50191 0.523586" mass="0.0257193" diaginertia="6.56033e-06 5.56532e-06 3.02948e-06"/>
          <joint armature="0.01" damping="0.4" stiffness="0.3" frictionloss="0.01" ref="0" springref="0" margin="0.01" name="ring_pip" pos="0 0 0" axis="0 0 1" range="-0.0873 1.6581"/>
          <geom name="ring_middle_phalange_3" conaffinity="1" contype="1" friction="1 0.005 0.001" margin="0.001" solimp="0.95 0.95 0.01" solref="0.008 1" type="mesh" rgba="0.958732 0.818161 0.775603 1" mesh="middle_phalange_3_collision"/>
          <body name="distal_finalshape_3" pos="0.0423 0 -1e-05" quat="0.999048 0.000871834 3.80651e-05 -0.0436194" gravcomp="0">
            <inertial pos="0.0280291 -0.000103785 -0.0133295" quat="0.490667 0.474831 0.50425 0.528691" mass="0.00905" diaginertia="2.9933e-06 2.44126e-06 1.2834e-06"/>
            <joint armature="0.01" damping="0.4" stiffness="0.3" frictionloss="0.01" ref="0" springref="0" margin="0.01" name="ring_dip" pos="0 0 0" axis="0 0 1" range="-0.0873 1.6581"/>
            <geom name="ring_distal_finalshape_3" conaffinity="1" contype="1" friction="1 0.005 0.001" margin="0.001" solimp="0.95 0.95 0.01" solref="0.008 1" type="mesh" rgba="0.513726 0.415686 0.733333 1" mesh="distal_finalshape_3_collision"/>
          </body>
        </body>
      </body>
    </body>
</body>  </worldbody>
<actuator><position ctrllimited="true" forcelimited="true" forcerange="-3 3" kp="100" gear="1" ctrlrange="0 1.5708" joint="thumb_cmc" name="thumb_cmc"></position>
<position ctrllimited="true" forcelimited="true" forcerange="-3 3" kp="100" gear="1" ctrlrange="-1.74533 0" joint="thumb_mcp_rot" name="thumb_mcp_rot"></position>
<position ctrllimited="true" forcelimited="true" forcerange="-3 3" kp="100" gear="1" ctrlrange="0 1.5708" joint="thumb_mcp" name="thumb_mcp"></position>
<position ctrllimited="true" forcelimited="true" forcerange="-3 3" kp="100" gear="1" ctrlrange="0 1.6581" joint="thumb_ip" name="thumb_ip"></position>
<position ctrllimited="true" forcelimited="true" forcerange="-3 3" kp="100" gear="1" ctrlrange="-0.436332 0.436332" joint="index_mcp_abadd" name="index_mcp_abadd"></position>
<position ctrllimited="true" forcelimited="true" forcerange="-3 3" kp="100" gear="1" ctrlrange="-0.0873 1.6581" joint="index_mcp" name="index_mcp"></position>
<position ctrllimited="true" forcelimited="true" forcerange="-3 3" kp="100" gear="1" ctrlrange="-0.0873 1.6581" joint="index_pip" name="index_pip"></position>
<position ctrllimited="true" forcelimited="true" forcerange="-3 3" kp="100" gear="1" ctrlrange="-0.0873 1.6581" joint="index_dip" name="index_dip"></position>
<position ctrllimited="true" forcelimited="true" forcerange="-3 3" kp="100" gear="1" ctrlrange="-0.436332 0.436332" joint="middle_mcp_abadd" name="middle_mcp_abadd"></position>
<position ctrllimited="true" forcelimited="true" forcerange="-3 3" kp="100" gear="1" ctrlrange="-0.0873 1.6581" joint="middle_mcp" name="middle_mcp"></position>
<position ctrllimited="true" forcelimited="true" forcerange="-3 3" kp="100" gear="1" ctrlrange="-0.0873 1.6581" joint="middle_pip" name="middle_pip"></position>
<position ctrllimited="true" forcelimited="true" forcerange="-3 3" kp="100" gear="1" ctrlrange="-0.0873 1.6581" joint="middle_dip" name="middle_dip"></position>
<position ctrllimited="true" forcelimited="true" forcerange="-3 3" kp="100" gear="1" ctrlrange="-0.436332 0.436332" joint="ring_mcp_abadd" name="ring_mcp_abadd"></position>
<position ctrllimited="true" forcelimited="true" forcerange="-3 3" kp="100" gear="1" ctrlrange="-0.0873 1.6581" joint="ring_mcp" name="ring_mcp"></position>
<position ctrllimited="true" forcelimited="true" forcerange="-3 3" kp="100" gear="1" ctrlrange="-0.0873 1.6581" joint="ring_pip" name="ring_pip"></position>
<position ctrllimited="true" forcelimited="true" forcerange="-3 3" kp="100" gear="1" ctrlrange="-0.0873 1.6581" joint="ring_dip" name="ring_dip"></position>
</actuator>
<contact><pair geom1="thumb_proximal_phalange" geom2="index_mcp_3" condim="3" friction="1 0.005 0.001" margin="0.0005" solimp="0.95 0.95 0.01" solref="0.008 1" /><pair geom1="thumb_proximal_phalange" geom2="index_proximal_phalange_2" condim="3" friction="1 0.005 0.001" margin="0.0005" solimp="0.95 0.95 0.01" solref="0.008 1" /><pair geom1="thumb_proximal_phalange" geom2="index_middle_phalange" condim="3" friction="1 0.005 0.001" margin="0.0005" solimp="0.95 0.95 0.01" solref="0.008 1" /><pair geom1="thumb_proximal_phalange" geom2="index_distal_finalshape" condim="3" friction="1 0.005 0.001" margin="0.0005" solimp="0.95 0.95 0.01" solref="0.008 1" /><pair geom1="thumb_proximal_phalange" geom2="middle_mcp_3_2" condim="3" friction="1 0.005 0.001" margin="0.0005" solimp="0.95 0.95 0.01" solref="0.008 1" /><pair geom1="thumb_proximal_phalange" geom2="middle_proximal_phalange_3" condim="3" friction="1 0.005 0.001" margin="0.0005" solimp="0.95 0.95 0.01" solref="0.008 1" /><pair geom1="thumb_proximal_phalange" geom2="middle_middle_phalange_2" condim="3" friction="1 0.005 0.001" margin="0.0005" solimp="0.95 0.95 0.01" solref="0.008 1" /><pair geom1="thumb_proximal_phalange" geom2="middle_distal_finalshape_2" condim="3" friction="1 0.005 0.001" margin="0.0005" solimp="0.95 0.95 0.01" solref="0.008 1" /><pair geom1="thumb_proximal_phalange" geom2="ring_mcp_3_3" condim="3" friction="1 0.005 0.001" margin="0.0005" solimp="0.95 0.95 0.01" solref="0.008 1" /><pair geom1="thumb_proximal_phalange" geom2="ring_proximal_phalange_4" condim="3" friction="1 0.005 0.001" margin="0.0005" solimp="0.95 0.95 0.01" solref="0.008 1" /><pair geom1="thumb_proximal_phalange" geom2="ring_middle_phalange_3" condim="3" friction="1 0.005 0.001" margin="0.0005" solimp="0.95 0.95 0.01" solref="0.008 1" /><pair geom1="thumb_proximal_phalange" geom2="ring_distal_finalshape_3" condim="3" friction="1 0.005 0.001" margin="0.0005" solimp="0.95 0.95 0.01" solref="0.008 1" /><pair geom1="handbase_and_motors" geom2="thumb_thumb_distal" condim="3" friction="1 0.005 0.001" margin="0.0005" solimp="0.95 0.95 0.01" solref="0.008 1" /><pair geom1="thumb_thumb_distal" geom2="index_mcp_3" condim="3" friction="1 0.005 0.001" margin="0.0005" solimp="0.95 0.95 0.01" solref="0.008 1" /><pair geom1="thumb_thumb_distal" geom2="index_proximal_phalange_2" condim="3" friction="1 0.005 0.001" margin="0.0005" solimp="0.95 0.95 0.01" solref="0.008 1" /><pair geom1="thumb_thumb_distal" geom2="index_middle_phalange" condim="3" friction="1 0.005 0.001" margin="0.0005" solimp="0.95 0.95 0.01" solref="0.008 1" /><pair geom1="thumb_thumb_distal" geom2="index_distal_finalshape" condim="3" friction="1 0.005 0.001" margin="0.0005" solimp="0.95 0.95 0.01" solref="0.008 1" /><pair geom1="thumb_thumb_distal" geom2="middle_mcp_3_2" condim="3" friction="1 0.005 0.001" margin="0.0005" solimp="0.95 0.95 0.01" solref="0.008 1" /><pair geom1="thumb_thumb_distal" geom2="middle_proximal_phalange_3" condim="3" friction="1 0.005 0.001" margin="0.0005" solimp="0.95 0.95 0.01" solref="0.008 1" /><pair geom1="thumb_thumb_distal" geom2="middle_middle_phalange_2" condim="3" friction="1 0.005 0.001" margin="0.0005" solimp="0.95 0.95 0.01" solref="0.008 1" /><pair geom1="thumb_thumb_distal" geom2="middle_distal_finalshape_2" condim="3" friction="1 0.005 0.001" margin="0.0005" solimp="0.95 0.95 0.01" solref="0.008 1" /><pair geom1="thumb_thumb_distal" geom2="ring_mcp_3_3" condim="3" friction="1 0.005 0.001" margin="0.0005" solimp="0.95 0.95 0.01" solref="0.008 1" /><pair geom1="thumb_thumb_distal" geom2="ring_proximal_phalange_4" condim="3" friction="1 0.005 0.001" margin="0.0005" solimp="0.95 0.95 0.01" solref="0.008 1" /><pair geom1="thumb_thumb_distal" geom2="ring_middle_phalange_3" condim="3" friction="1 0.005 0.001" margin="0.0005" solimp="0.95 0.95 0.01" solref="0.008 1" /><pair geom1="thumb_thumb_distal" geom2="ring_distal_finalshape_3" condim="3" friction="1 0.005 0.001" margin="0.0005" solimp="0.95 0.95 0.01" solref="0.008 1" /><pair geom1="index_mcp_3" geom2="index_distal_finalshape" condim="3" friction="1 0.005 0.001" margin="0.0005" solimp="0.95 0.95 0.01" solref="0.008 1" /><pair geom1="index_proximal_phalange_2" geom2="index_distal_finalshape" condim="3" friction="1 0.005 0.001" margin="0.0005" solimp="0.95 0.95 0.01" solref="0.008 1" /><pair geom1="index_mcp_3" geom2="middle_mcp_3_2" condim="3" friction="1 0.005 0.001" margin="0.0005" solimp="0.95 0.95 0.01" solref="0.008 1" /><pair geom1="index_mcp_3" geom2="middle_proximal_phalange_3" condim="3" friction="1 0.005 0.001" margin="0.0005" solimp="0.95 0.95 0.01" solref="0.008 1" /><pair geom1="index_mcp_3" geom2="middle_middle_phalange_2" condim="3" friction="1 0.005 0.001" margin="0.0005" solimp="0.95 0.95 0.01" solref="0.008 1" /><pair geom1="index_mcp_3" geom2="middle_distal_finalshape_2" condim="3" friction="1 0.005 0.001" margin="0.0005" solimp="0.95 0.95 0.01" solref="0.008 1" /><pair geom1="index_mcp_3" geom2="ring_mcp_3_3" condim="3" friction="1 0.005 0.001" margin="0.0005" solimp="0.95 0.95 0.01" solref="0.008 1" /><pair geom1="index_mcp_3" geom2="ring_proximal_phalange_4" condim="3" friction="1 0.005 0.001" margin="0.0005" solimp="0.95 0.95 0.01" solref="0.008 1" /><pair geom1="index_mcp_3" geom2="ring_middle_phalange_3" condim="3" friction="1 0.005 0.001" margin="0.0005" solimp="0.95 0.95 0.01" solref="0.008 1" /><pair geom1="index_mcp_3" geom2="ring_distal_finalshape_3" condim="3" friction="1 0.005 0.001" margin="0.0005" solimp="0.95 0.95 0.01" solref="0.008 1" /><pair geom1="index_proximal_phalange_2" geom2="middle_mcp_3_2" condim="3" friction="1 0.005 0.001" margin="0.0005" solimp="0.95 0.95 0.01" solref="0.008 1" /><pair geom1="index_proximal_phalange_2" geom2="middle_proximal_phalange_3" condim="3" friction="1 0.005 0.001" margin="0.0005" solimp="0.95 0.95 0.01" solref="0.008 1" /><pair geom1="index_proximal_phalange_2" geom2="middle_middle_phalange_2" condim="3" friction="1 0.005 0.001" margin="0.0005" solimp="0.95 0.95 0.01" solref="0.008 1" /><pair geom1="index_proximal_phalange_2" geom2="middle_distal_finalshape_2" condim="3" friction="1 0.005 0.001" margin="0.0005" solimp="0.95 0.95 0.01" solref="0.008 1" /><pair geom1="index_proximal_phalange_2" geom2="ring_mcp_3_3" condim="3" friction="1 0.005 0.001" margin="0.0005" solimp="0.95 0.95 0.01" solref="0.008 1" /><pair geom1="index_proximal_phalange_2" geom2="ring_proximal_phalange_4" condim="3" friction="1 0.005 0.001" margin="0.0005" solimp="0.95 0.95 0.01" solref="0.008 1" /><pair geom1="index_proximal_phalange_2" geom2="ring_middle_phalange_3" condim="3" friction="1 0.005 0.001" margin="0.0005" solimp="0.95 0.95 0.01" solref="0.008 1" /><pair geom1="index_proximal_phalange_2" geom2="ring_distal_finalshape_3" condim="3" friction="1 0.005 0.001" margin="0.0005" solimp="0.95 0.95 0.01" solref="0.008 1" /><pair geom1="index_middle_phalange" geom2="middle_mcp_3_2" condim="3" friction="1 0.005 0.001" margin="0.0005" solimp="0.95 0.95 0.01" solref="0.008 1" /><pair geom1="index_middle_phalange" geom2="middle_proximal_phalange_3" condim="3" friction="1 0.005 0.001" margin="0.0005" solimp="0.95 0.95 0.01" solref="0.008 1" /><pair geom1="index_middle_phalange" geom2="middle_middle_phalange_2" condim="3" friction="1 0.005 0.001" margin="0.0005" solimp="0.95 0.95 0.01" solref="0.008 1" /><pair geom1="index_middle_phalange" geom2="middle_distal_finalshape_2" condim="3" friction="1 0.005 0.001" margin="0.0005" solimp="0.95 0.95 0.01" solref="0.008 1" /><pair geom1="index_middle_phalange" geom2="ring_mcp_3_3" condim="3" friction="1 0.005 0.001" margin="0.0005" solimp="0.95 0.95 0.01" solref="0.008 1" /><pair geom1="index_middle_phalange" geom2="ring_proximal_phalange_4" condim="3" friction="1 0.005 0.001" margin="0.0005" solimp="0.95 0.95 0.01" solref="0.008 1" /><pair geom1="index_middle_phalange" geom2="ring_middle_phalange_3" condim="3" friction="1 0.005 0.001" margin="0.0005" solimp="0.95 0.95 0.01" solref="0.008 1" /><pair geom1="index_middle_phalange" geom2="ring_distal_finalshape_3" condim="3" friction="1 0.005 0.001" margin="0.0005" solimp="0.95 0.95 0.01" solref="0.008 1" /><pair geom1="handbase_and_motors" geom2="index_distal_finalshape" condim="3" friction="1 0.005 0.001" margin="0.0005" solimp="0.95 0.95 0.01" solref="0.008 1" /><pair geom1="index_distal_finalshape" geom2="middle_mcp_3_2" condim="3" friction="1 0.005 0.001" margin="0.0005" solimp="0.95 0.95 0.01" solref="0.008 1" /><pair geom1="index_distal_finalshape" geom2="middle_proximal_phalange_3" condim="3" friction="1 0.005 0.001" margin="0.0005" solimp="0.95 0.95 0.01" solref="0.008 1" /><pair geom1="index_distal_finalshape" geom2="middle_middle_phalange_2" condim="3" friction="1 0.005 0.001" margin="0.0005" solimp="0.95 0.95 0.01" solref="0.008 1" /><pair geom1="index_distal_finalshape" geom2="middle_distal_finalshape_2" condim="3" friction="1 0.005 0.001" margin="0.0005" solimp="0.95 0.95 0.01" solref="0.008 1" /><pair geom1="index_distal_finalshape" geom2="ring_mcp_3_3" condim="3" friction="1 0.005 0.001" margin="0.0005" solimp="0.95 0.95 0.01" solref="0.008 1" /><pair geom1="index_distal_finalshape" geom2="ring_proximal_phalange_4" condim="3" friction="1 0.005 0.001" margin="0.0005" solimp="0.95 0.95 0.01" solref="0.008 1" /><pair geom1="index_distal_finalshape" geom2="ring_middle_phalange_3" condim="3" friction="1 0.005 0.001" margin="0.0005" solimp="0.95 0.95 0.01" solref="0.008 1" /><pair geom1="index_distal_finalshape" geom2="ring_distal_finalshape_3" condim="3" friction="1 0.005 0.001" margin="0.0005" solimp="0.95 0.95 0.01" solref="0.008 1" /><pair geom1="middle_mcp_3_2" geom2="middle_distal_finalshape_2" condim="3" friction="1 0.005 0.001" margin="0.0005" solimp="0.95 0.95 0.01" solref="0.008 1" /><pair geom1="middle_proximal_phalange_3" geom2="middle_distal_finalshape_2" condim="3" friction="1 0.005 0.001" margin="0.0005" solimp="0.95 0.95 0.01" solref="0.008 1" /><pair geom1="middle_mcp_3_2" geom2="ring_mcp_3_3" condim="3" friction="1 0.005 0.001" margin="0.0005" solimp="0.95 0.95 0.01" solref="0.008 1" /><pair geom1="middle_mcp_3_2" geom2="ring_proximal_phalange_4" condim="3" friction="1 0.005 0.001" margin="0.0005" solimp="0.95 0.95 0.01" solref="0.008 1" /><pair geom1="middle_mcp_3_2" geom2="ring_middle_phalange_3" condim="3" friction="1 0.005 0.001" margin="0.0005" solimp="0.95 0.95 0.01" solref="0.008 1" /><pair geom1="middle_mcp_3_2" geom2="ring_distal_finalshape_3" condim="3" friction="1 0.005 0.001" margin="0.0005" solimp="0.95 0.95 0.01" solref="0.008 1" /><pair geom1="middle_proximal_phalange_3" geom2="ring_mcp_3_3" condim="3" friction="1 0.005 0.001" margin="0.0005" solimp="0.95 0.95 0.01" solref="0.008 1" /><pair geom1="middle_proximal_phalange_3" geom2="ring_proximal_phalange_4" condim="3" friction="1 0.005 0.001" margin="0.0005" solimp="0.95 0.95 0.01" solref="0.008 1" /><pair geom1="middle_proximal_phalange_3" geom2="ring_middle_phalange_3" condim="3" friction="1 0.005 0.001" margin="0.0005" solimp="0.95 0.95 0.01" solref="0.008 1" /><pair geom1="middle_proximal_phalange_3" geom2="ring_distal_finalshape_3" condim="3" friction="1 0.005 0.001" margin="0.0005" solimp="0.95 0.95 0.01" solref="0.008 1" /><pair geom1="middle_middle_phalange_2" geom2="ring_mcp_3_3" condim="3" friction="1 0.005 0.001" margin="0.0005" solimp="0.95 0.95 0.01" solref="0.008 1" /><pair geom1="middle_middle_phalange_2" geom2="ring_proximal_phalange_4" condim="3" friction="1 0.005 0.001" margin="0.0005" solimp="0.95 0.95 0.01" solref="0.008 1" /><pair geom1="middle_middle_phalange_2" geom2="ring_middle_phalange_3" condim="3" friction="1 0.005 0.001" margin="0.0005" solimp="0.95 0.95 0.01" solref="0.008 1" /><pair geom1="middle_middle_phalange_2" geom2="ring_distal_finalshape_3" condim="3" friction="1 0.005 0.001" margin="0.0005" solimp="0.95 0.95 0.01" solref="0.008 1" /><pair geom1="handbase_and_motors" geom2="middle_distal_finalshape_2" condim="3" friction="1 0.005 0.001" margin="0.0005" solimp="0.95 0.95 0.01" solref="0.008 1" /><pair geom1="middle_distal_finalshape_2" geom2="ring_mcp_3_3" condim="3" friction="1 0.005 0.001" margin="0.0005" solimp="0.95 0.95 0.01" solref="0.008 1" /><pair geom1="middle_distal_finalshape_2" geom2="ring_proximal_phalange_4" condim="3" friction="1 0.005 0.001" margin="0.0005" solimp="0.95 0.95 0.01" solref="0.008 1" /><pair geom1="middle_distal_finalshape_2" geom2="ring_middle_phalange_3" condim="3" friction="1 0.005 0.001" margin="0.0005" solimp="0.95 0.95 0.01" solref="0.008 1" /><pair geom1="middle_distal_finalshape_2" geom2="ring_distal_finalshape_3" condim="3" friction="1 0.005 0.001" margin="0.0005" solimp="0.95 0.95 0.01" solref="0.008 1" /><pair geom1="ring_mcp_3_3" geom2="ring_distal_finalshape_3" condim="3" friction="1 0.005 0.001" margin="0.0005" solimp="0.95 0.95 0.01" solref="0.008 1" /><pair geom1="ring_proximal_phalange_4" geom2="ring_distal_finalshape_3" condim="3" friction="1 0.005 0.001" margin="0.0005" solimp="0.95 0.95 0.01" solref="0.008 1" /><pair geom1="handbase_and_motors" geom2="ring_distal_finalshape_3" condim="3" friction="1 0.005 0.001" margin="0.0005" solimp="0.95 0.95 0.01" solref="0.008 1" /></contact></mujoco>
